[2024-06-24T04:14:11.554+0000] {taskinstance.py:1159} INFO - Dependencies all met for dep_context=non-requeueable deps ti=<TaskInstance: snowflake_connector3.snowfalke_task1 manual__2024-06-24T04:14:09.322012+00:00 [queued]>
[2024-06-24T04:14:11.566+0000] {taskinstance.py:1159} INFO - Dependencies all met for dep_context=requeueable deps ti=<TaskInstance: snowflake_connector3.snowfalke_task1 manual__2024-06-24T04:14:09.322012+00:00 [queued]>
[2024-06-24T04:14:11.567+0000] {taskinstance.py:1361} INFO - Starting attempt 1 of 1
[2024-06-24T04:14:11.584+0000] {taskinstance.py:1382} INFO - Executing <Task(SnowflakeOperator): snowfalke_task1> on 2024-06-24 04:14:09.322012+00:00
[2024-06-24T04:14:11.592+0000] {standard_task_runner.py:57} INFO - Started process 1958 to run task
[2024-06-24T04:14:11.598+0000] {standard_task_runner.py:84} INFO - Running: ['***', 'tasks', 'run', 'snowflake_connector3', 'snowfalke_task1', 'manual__2024-06-24T04:14:09.322012+00:00', '--job-id', '25', '--raw', '--subdir', 'DAGS_FOLDER/staging/rbroker/dag.py', '--cfg-path', '/tmp/tmph6wzaf1b']
[2024-06-24T04:14:11.610+0000] {standard_task_runner.py:85} INFO - Job 25: Subtask snowfalke_task1
[2024-06-24T04:14:11.713+0000] {task_command.py:416} INFO - Running <TaskInstance: snowflake_connector3.snowfalke_task1 manual__2024-06-24T04:14:09.322012+00:00 [running]> on host b00a3d1afa8e
[2024-06-24T04:14:11.829+0000] {taskinstance.py:1662} INFO - Exporting env vars: AIRFLOW_CTX_DAG_OWNER='Airflow' AIRFLOW_CTX_DAG_ID='snowflake_connector3' AIRFLOW_CTX_TASK_ID='snowfalke_task1' AIRFLOW_CTX_EXECUTION_DATE='2024-06-24T04:14:09.322012+00:00' AIRFLOW_CTX_TRY_NUMBER='1' AIRFLOW_CTX_DAG_RUN_ID='manual__2024-06-24T04:14:09.322012+00:00'
[2024-06-24T04:14:11.831+0000] {sql.py:274} INFO - Executing: ['select 1;', 'show tables in database abcd_db;']
[2024-06-24T04:14:11.858+0000] {taskinstance.py:1937} ERROR - Task failed with exception
Traceback (most recent call last):
  File "/home/airflow/.local/lib/python3.8/site-packages/airflow/providers/common/sql/operators/sql.py", line 275, in execute
    hook = self.get_db_hook()
  File "/home/airflow/.local/lib/python3.8/site-packages/airflow/providers/common/sql/operators/sql.py", line 186, in get_db_hook
    return self._hook
  File "/usr/local/lib/python3.8/functools.py", line 967, in __get__
    val = self.func(instance)
  File "/home/airflow/.local/lib/python3.8/site-packages/airflow/providers/common/sql/operators/sql.py", line 148, in _hook
    conn = BaseHook.get_connection(conn_id)
  File "/home/airflow/.local/lib/python3.8/site-packages/airflow/hooks/base.py", line 72, in get_connection
    conn = Connection.get_connection_from_secrets(conn_id)
  File "/home/airflow/.local/lib/python3.8/site-packages/airflow/models/connection.py", line 477, in get_connection_from_secrets
    raise AirflowNotFoundException(f"The conn_id `{conn_id}` isn't defined")
airflow.exceptions.AirflowNotFoundException: The conn_id `snowflake_conn` isn't defined
[2024-06-24T04:14:11.868+0000] {taskinstance.py:1400} INFO - Marking task as FAILED. dag_id=snowflake_connector3, task_id=snowfalke_task1, execution_date=20240624T041409, start_date=20240624T041411, end_date=20240624T041411
[2024-06-24T04:14:11.884+0000] {standard_task_runner.py:104} ERROR - Failed to execute job 25 for task snowfalke_task1 (The conn_id `snowflake_conn` isn't defined; 1958)
[2024-06-24T04:14:11.932+0000] {local_task_job_runner.py:228} INFO - Task exited with return code 1
[2024-06-24T04:14:11.962+0000] {taskinstance.py:2778} INFO - 0 downstream tasks scheduled from follow-on schedule check
