[2024-06-24T04:38:52.065+0000] {taskinstance.py:1159} INFO - Dependencies all met for dep_context=non-requeueable deps ti=<TaskInstance: snowflake_connector3.snowfalke_task1 manual__2024-06-24T04:38:49.717074+00:00 [queued]>
[2024-06-24T04:38:52.076+0000] {taskinstance.py:1159} INFO - Dependencies all met for dep_context=requeueable deps ti=<TaskInstance: snowflake_connector3.snowfalke_task1 manual__2024-06-24T04:38:49.717074+00:00 [queued]>
[2024-06-24T04:38:52.077+0000] {taskinstance.py:1361} INFO - Starting attempt 1 of 1
[2024-06-24T04:38:52.093+0000] {taskinstance.py:1382} INFO - Executing <Task(SnowflakeOperator): snowfalke_task1> on 2024-06-24 04:38:49.717074+00:00
[2024-06-24T04:38:52.102+0000] {standard_task_runner.py:57} INFO - Started process 2364 to run task
[2024-06-24T04:38:52.106+0000] {standard_task_runner.py:84} INFO - Running: ['***', 'tasks', 'run', 'snowflake_connector3', 'snowfalke_task1', 'manual__2024-06-24T04:38:49.717074+00:00', '--job-id', '35', '--raw', '--subdir', 'DAGS_FOLDER/staging/rbroker/dag.py', '--cfg-path', '/tmp/tmpaz5c2_jy']
[2024-06-24T04:38:52.111+0000] {standard_task_runner.py:85} INFO - Job 35: Subtask snowfalke_task1
[2024-06-24T04:38:52.174+0000] {task_command.py:416} INFO - Running <TaskInstance: snowflake_connector3.snowfalke_task1 manual__2024-06-24T04:38:49.717074+00:00 [running]> on host b00a3d1afa8e
[2024-06-24T04:38:52.278+0000] {taskinstance.py:1662} INFO - Exporting env vars: AIRFLOW_CTX_DAG_OWNER='Airflow' AIRFLOW_CTX_DAG_ID='snowflake_connector3' AIRFLOW_CTX_TASK_ID='snowfalke_task1' AIRFLOW_CTX_EXECUTION_DATE='2024-06-24T04:38:49.717074+00:00' AIRFLOW_CTX_TRY_NUMBER='1' AIRFLOW_CTX_DAG_RUN_ID='manual__2024-06-24T04:38:49.717074+00:00'
[2024-06-24T04:38:52.279+0000] {sql.py:274} INFO - Executing: ['select 1;', 'show tables in database abcd_db;']
[2024-06-24T04:38:52.293+0000] {base.py:73} INFO - Using connection ID 'my_snowflake_conn' for task execution.
[2024-06-24T04:38:52.305+0000] {base.py:73} INFO - Using connection ID 'my_snowflake_conn' for task execution.
[2024-06-24T04:38:52.307+0000] {connection.py:334} INFO - Snowflake Connector for Python Version: 3.3.1, Python Version: 3.8.18, Platform: Linux-6.3.13-linuxkit-x86_64-with-glibc2.2.5
[2024-06-24T04:38:52.309+0000] {connection.py:1103} INFO - This connection is in OCSP Fail Open Mode. TLS Certificates would be checked for validity and revocation status. Any other Certificate Revocation related exceptions or OCSP Responder failures would be disregarded in favor of connectivity.
[2024-06-24T04:38:52.309+0000] {connection.py:1113} INFO - THIS CONNECTION IS IN INSECURE MODE. IT MEANS THE CERTIFICATE WILL BE VALIDATED BUT THE CERTIFICATE REVOCATION STATUS WILL NOT BE CHECKED.
[2024-06-24T04:38:52.310+0000] {connection.py:1121} INFO - Setting use_openssl_only mode to False
[2024-06-24T04:38:52.567+0000] {ssl_wrap_socket.py:100} INFO - THIS CONNECTION IS IN INSECURE MODE. IT MEANS THE CERTIFICATE WILL BE VALIDATED BUT THE CERTIFICATE REVOCATION STATUS WILL NOT BE CHECKED.
[2024-06-24T04:38:52.575+0000] {connection.py:547} WARNING - Certificate did not match expected hostname: rtapgyk.ca-central-1.snowflakecomputing.com. Certificate: {'subject': ((('commonName', '*.prod3.us-west-2.snowflakecomputing.com'),),), 'subjectAltName': [('DNS', '*.prod3.us-west-2.snowflakecomputing.com'), ('DNS', '*.us-west-2.snowflakecomputing.com'), ('DNS', '*.global.snowflakecomputing.com'), ('DNS', '*.snowflakecomputing.com'), ('DNS', '*.prod3.us-west-2.aws.snowflakecomputing.com')]}
[2024-06-24T04:38:52.577+0000] {connectionpool.py:812} WARNING - Retrying (Retry(total=0, connect=None, read=None, redirect=None, status=None)) after connection broken by 'SSLError(CertificateError("hostname 'rtapgyk.ca-central-1.snowflakecomputing.com' doesn't match either of '*.prod3.us-west-2.snowflakecomputing.com', '*.us-west-2.snowflakecomputing.com', '*.global.snowflakecomputing.com', '*.snowflakecomputing.com', '*.prod3.us-west-2.aws.snowflakecomputing.com'"))': /session/v1/login-request?request_id=51dfb7f4-ec97-43c8-b731-21516aac2a0c&databaseName=WDP_DEV&schemaName=staging&warehouse=COMPUTE_WH&roleName=ACCOUNTADMIN&request_guid=4668b485-7391-4925-aa3d-a366bacadd8e
[2024-06-24T04:38:52.817+0000] {ssl_wrap_socket.py:100} INFO - THIS CONNECTION IS IN INSECURE MODE. IT MEANS THE CERTIFICATE WILL BE VALIDATED BUT THE CERTIFICATE REVOCATION STATUS WILL NOT BE CHECKED.
[2024-06-24T04:38:52.821+0000] {connection.py:547} WARNING - Certificate did not match expected hostname: rtapgyk.ca-central-1.snowflakecomputing.com. Certificate: {'subject': ((('commonName', '*.prod3.us-west-2.snowflakecomputing.com'),),), 'subjectAltName': [('DNS', '*.prod3.us-west-2.snowflakecomputing.com'), ('DNS', '*.us-west-2.snowflakecomputing.com'), ('DNS', '*.global.snowflakecomputing.com'), ('DNS', '*.snowflakecomputing.com'), ('DNS', '*.prod3.us-west-2.aws.snowflakecomputing.com')]}
[2024-06-24T04:38:52.829+0000] {network.py:1037} ERROR - Failed to get the response. Hanging? method: post, url: https://RTAPGYK.ca-central-1.snowflakecomputing.com:443/session/v1/login-request?request_id=51dfb7f4-ec97-43c8-b731-21516aac2a0c&databaseName=WDP_DEV&schemaName=staging&warehouse=COMPUTE_WH&roleName=ACCOUNTADMIN&request_guid=4668b485-7391-4925-aa3d-a366bacadd8e, headers:{'Content-Type': 'application/json', 'accept': 'application/snowflake', 'User-Agent': 'PythonConnector/3.3.1 (Linux-6.3.13-linuxkit-x86_64-with-glibc2.2.5) CPython/3.8.18', 'Content-Encoding': 'gzip'}, data: {"data": {"CLIENT_APP_ID": "PythonConnector", "CLIENT_APP_VERSION": "3.3.1", "SVN_REVISION": null, "ACCOUNT_NAME": "RTAPGYK", "LOGIN_NAME": "mmahmoud", "CLIENT_ENVIRONMENT": {"APPLICATION": "AIRFLOW", "OS": "Linux", "OS_VERSION": "Linux-6.3.13-linuxkit-x86_64-with-glibc2.2.5", "PYTHON_VERSION": "3.8.18", "PYTHON_RUNTIME": "CPython", "PYTHON_COMPILER": "GCC 10.2.1 20210110", "OCSP_MODE": "INSECURE", "TRACING": 20, "LOGIN_TIMEOUT": 120, "NETWORK_TIMEOUT": null}, "PASSWORD": "**** "SESSION_PARAMETERS": {"CLIENT_PREFETCH_THREADS": 4}}}
[2024-06-24T04:38:54.073+0000] {ssl_wrap_socket.py:100} INFO - THIS CONNECTION IS IN INSECURE MODE. IT MEANS THE CERTIFICATE WILL BE VALIDATED BUT THE CERTIFICATE REVOCATION STATUS WILL NOT BE CHECKED.
[2024-06-24T04:38:54.077+0000] {connection.py:547} WARNING - Certificate did not match expected hostname: rtapgyk.ca-central-1.snowflakecomputing.com. Certificate: {'subject': ((('commonName', '*.prod3.us-west-2.snowflakecomputing.com'),),), 'subjectAltName': [('DNS', '*.prod3.us-west-2.snowflakecomputing.com'), ('DNS', '*.us-west-2.snowflakecomputing.com'), ('DNS', '*.global.snowflakecomputing.com'), ('DNS', '*.snowflakecomputing.com'), ('DNS', '*.prod3.us-west-2.aws.snowflakecomputing.com')]}
[2024-06-24T04:38:54.079+0000] {connectionpool.py:812} WARNING - Retrying (Retry(total=0, connect=None, read=None, redirect=None, status=None)) after connection broken by 'SSLError(CertificateError("hostname 'rtapgyk.ca-central-1.snowflakecomputing.com' doesn't match either of '*.prod3.us-west-2.snowflakecomputing.com', '*.us-west-2.snowflakecomputing.com', '*.global.snowflakecomputing.com', '*.snowflakecomputing.com', '*.prod3.us-west-2.aws.snowflakecomputing.com'"))': /session/v1/login-request?request_id=0726e0d4-198c-4865-821b-d7f33ddab0d6&databaseName=WDP_DEV&schemaName=staging&warehouse=COMPUTE_WH&roleName=ACCOUNTADMIN&request_guid=9fd4d17d-f9d5-426a-8c2a-5ac068dff240
[2024-06-24T04:38:54.311+0000] {ssl_wrap_socket.py:100} INFO - THIS CONNECTION IS IN INSECURE MODE. IT MEANS THE CERTIFICATE WILL BE VALIDATED BUT THE CERTIFICATE REVOCATION STATUS WILL NOT BE CHECKED.
[2024-06-24T04:38:54.313+0000] {connection.py:547} WARNING - Certificate did not match expected hostname: rtapgyk.ca-central-1.snowflakecomputing.com. Certificate: {'subject': ((('commonName', '*.prod3.us-west-2.snowflakecomputing.com'),),), 'subjectAltName': [('DNS', '*.prod3.us-west-2.snowflakecomputing.com'), ('DNS', '*.us-west-2.snowflakecomputing.com'), ('DNS', '*.global.snowflakecomputing.com'), ('DNS', '*.snowflakecomputing.com'), ('DNS', '*.prod3.us-west-2.aws.snowflakecomputing.com')]}
[2024-06-24T04:38:54.318+0000] {network.py:1037} ERROR - Failed to get the response. Hanging? method: post, url: https://RTAPGYK.ca-central-1.snowflakecomputing.com:443/session/v1/login-request?request_id=0726e0d4-198c-4865-821b-d7f33ddab0d6&databaseName=WDP_DEV&schemaName=staging&warehouse=COMPUTE_WH&roleName=ACCOUNTADMIN&request_guid=9fd4d17d-f9d5-426a-8c2a-5ac068dff240, headers:{'Content-Type': 'application/json', 'accept': 'application/snowflake', 'User-Agent': 'PythonConnector/3.3.1 (Linux-6.3.13-linuxkit-x86_64-with-glibc2.2.5) CPython/3.8.18', 'Content-Encoding': 'gzip'}, data: {"data": {"CLIENT_APP_ID": "PythonConnector", "CLIENT_APP_VERSION": "3.3.1", "SVN_REVISION": null, "ACCOUNT_NAME": "RTAPGYK", "LOGIN_NAME": "mmahmoud", "CLIENT_ENVIRONMENT": {"APPLICATION": "AIRFLOW", "OS": "Linux", "OS_VERSION": "Linux-6.3.13-linuxkit-x86_64-with-glibc2.2.5", "PYTHON_VERSION": "3.8.18", "PYTHON_RUNTIME": "CPython", "PYTHON_COMPILER": "GCC 10.2.1 20210110", "OCSP_MODE": "INSECURE", "TRACING": 20, "LOGIN_TIMEOUT": 120, "NETWORK_TIMEOUT": null}, "PASSWORD": "**** "SESSION_PARAMETERS": {"CLIENT_PREFETCH_THREADS": 4}}}
[2024-06-24T04:38:54.321+0000] {taskinstance.py:1937} ERROR - Task failed with exception
Traceback (most recent call last):
  File "/home/airflow/.local/lib/python3.8/site-packages/snowflake/connector/connection.py", line 1246, in _authenticate
    auth.authenticate(
  File "/home/airflow/.local/lib/python3.8/site-packages/snowflake/connector/auth/_auth.py", line 250, in authenticate
    ret = self._rest._post_request(
  File "/home/airflow/.local/lib/python3.8/site-packages/snowflake/connector/network.py", line 730, in _post_request
    ret = self.fetch(
  File "/home/airflow/.local/lib/python3.8/site-packages/snowflake/connector/network.py", line 849, in fetch
    ret = self._request_exec_wrapper(
  File "/home/airflow/.local/lib/python3.8/site-packages/snowflake/connector/network.py", line 987, in _request_exec_wrapper
    raise e
  File "/home/airflow/.local/lib/python3.8/site-packages/snowflake/connector/network.py", line 902, in _request_exec_wrapper
    self._handle_unknown_error(method, full_url, headers, data, conn)
  File "/home/airflow/.local/lib/python3.8/site-packages/snowflake/connector/network.py", line 1042, in _handle_unknown_error
    Error.errorhandler_wrapper(
  File "/home/airflow/.local/lib/python3.8/site-packages/snowflake/connector/errors.py", line 290, in errorhandler_wrapper
    handed_over = Error.hand_to_other_handler(
  File "/home/airflow/.local/lib/python3.8/site-packages/snowflake/connector/errors.py", line 348, in hand_to_other_handler
    connection.errorhandler(connection, cursor, error_class, error_value)
  File "/home/airflow/.local/lib/python3.8/site-packages/snowflake/connector/errors.py", line 221, in default_errorhandler
    raise error_class(
snowflake.connector.errors.OperationalError: 250003: 250003: Failed to get the response. Hanging? method: post, url: https://RTAPGYK.ca-central-1.snowflakecomputing.com:443/session/v1/login-request?request_id=51dfb7f4-ec97-43c8-b731-21516aac2a0c&databaseName=WDP_DEV&schemaName=staging&warehouse=COMPUTE_WH&roleName=ACCOUNTADMIN&request_guid=4668b485-7391-4925-aa3d-a366bacadd8e

The above exception was the direct cause of the following exception:

Traceback (most recent call last):
  File "/home/airflow/.local/lib/python3.8/site-packages/airflow/providers/common/sql/operators/sql.py", line 280, in execute
    output = hook.run(
  File "/home/airflow/.local/lib/python3.8/site-packages/airflow/providers/snowflake/hooks/snowflake.py", line 382, in run
    with closing(self.get_conn()) as conn:
  File "/home/airflow/.local/lib/python3.8/site-packages/airflow/providers/snowflake/hooks/snowflake.py", line 276, in get_conn
    conn = connector.connect(**conn_config)
  File "/home/airflow/.local/lib/python3.8/site-packages/snowflake/connector/__init__.py", line 54, in Connect
    return SnowflakeConnection(**kwargs)
  File "/home/airflow/.local/lib/python3.8/site-packages/snowflake/connector/connection.py", line 382, in __init__
    self.connect(**kwargs)
  File "/home/airflow/.local/lib/python3.8/site-packages/snowflake/connector/connection.py", line 662, in connect
    self.__open_connection()
  File "/home/airflow/.local/lib/python3.8/site-packages/snowflake/connector/connection.py", line 935, in __open_connection
    self.authenticate_with_retry(self.auth_class)
  File "/home/airflow/.local/lib/python3.8/site-packages/snowflake/connector/connection.py", line 1220, in authenticate_with_retry
    self._authenticate(auth_instance)
  File "/home/airflow/.local/lib/python3.8/site-packages/snowflake/connector/connection.py", line 1291, in _authenticate
    raise auth_op from e
  File "/home/airflow/.local/lib/python3.8/site-packages/snowflake/connector/connection.py", line 1268, in _authenticate
    auth_instance.handle_timeout(
  File "/home/airflow/.local/lib/python3.8/site-packages/snowflake/connector/auth/by_plugin.py", line 219, in handle_timeout
    raise error
snowflake.connector.errors.OperationalError: 250001: 250001: Could not connect to Snowflake backend after 1 attempt(s).Aborting
[2024-06-24T04:38:54.333+0000] {taskinstance.py:1400} INFO - Marking task as FAILED. dag_id=snowflake_connector3, task_id=snowfalke_task1, execution_date=20240624T043849, start_date=20240624T043852, end_date=20240624T043854
[2024-06-24T04:38:54.353+0000] {standard_task_runner.py:104} ERROR - Failed to execute job 35 for task snowfalke_task1 (250001: 250001: Could not connect to Snowflake backend after 1 attempt(s).Aborting; 2364)
[2024-06-24T04:38:54.393+0000] {local_task_job_runner.py:228} INFO - Task exited with return code 1
[2024-06-24T04:38:54.427+0000] {taskinstance.py:2778} INFO - 0 downstream tasks scheduled from follow-on schedule check
